[INFO   ] Logger: Record log in /storage/emulated/0/Python/Testes/.kivy/logs/kivy_22-04-11_4.txt
[INFO   ] Kivy: v2.0.0
[INFO   ] Kivy: Installed at "/data/user/0/ru.iiec.pydroid3/files/arm-linux-androideabi/lib/python3.9/site-packages/kivy/__init__.py"
[INFO   ] Python: v3.9.7 (default, Oct  9 2021, 08:02:40) 
[GCC 11.1.0]
[INFO   ] Python: Interpreter at "/data/user/0/ru.iiec.pydroid3/files/arm-linux-androideabi/bin/python3"
[INFO   ] Factory: 186 symbols loaded
[INFO   ] Image: Providers: img_tex, img_dds, img_sdl2 (img_pil, img_ffpyplayer ignored)
[INFO   ] Window: Provider: sdl2
[INFO   ] GL: Using the "OpenGL ES 2" graphics system
[INFO   ] GL: Backend used <sdl2>
[INFO   ] GL: OpenGL version <b'OpenGL ES 3.1 v1.r7p0-02rel0.4ea33e6671ff828e33c99c982634cd65'>
[INFO   ] GL: OpenGL vendor <b'ARM'>
[INFO   ] GL: OpenGL renderer <b'Mali-T720'>
[INFO   ] GL: OpenGL parsed version: 3, 1
[INFO   ] GL: Texture max size <8192>
[INFO   ] GL: Texture max units <16>
[INFO   ] Window: auto add sdl2 input provider
[INFO   ] Window: virtual keyboard not allowed, single mode, not docked
[INFO   ] Text: Provider: sdl2
[INFO   ] GL: NPOT texture support is available
[WARNING] Base: Unknown <android> provider
[INFO   ] Base: Start application main loop
[INFO   ] Base: Leaving application in progress...
[WARNING] stderr: Traceback (most recent call last):
[WARNING] stderr:   File "/storage/emulated/0/Python/Testes/__init__.py", line 29, in <module>
[WARNING] stderr:     Application().run()
[WARNING] stderr:   File "/data/user/0/ru.iiec.pydroid3/files/arm-linux-androideabi/lib/python3.9/site-packages/kivy/app.py", line 950, in run
[WARNING] stderr:     runTouchApp()
[WARNING] stderr:   File "/data/user/0/ru.iiec.pydroid3/files/arm-linux-androideabi/lib/python3.9/site-packages/kivy/base.py", line 582, in runTouchApp
[WARNING] stderr:     EventLoop.mainloop()
[WARNING] stderr:   File "/data/user/0/ru.iiec.pydroid3/files/arm-linux-androideabi/lib/python3.9/site-packages/kivy/base.py", line 347, in mainloop
[WARNING] stderr:     self.idle()
[WARNING] stderr:   File "/data/user/0/ru.iiec.pydroid3/files/arm-linux-androideabi/lib/python3.9/site-packages/kivy/base.py", line 391, in idle
[WARNING] stderr:     self.dispatch_input()
[WARNING] stderr:   File "/data/user/0/ru.iiec.pydroid3/files/arm-linux-androideabi/lib/python3.9/site-packages/kivy/base.py", line 342, in dispatch_input
[WARNING] stderr:     post_dispatch_input(*pop(0))
[WARNING] stderr:   File "/data/user/0/ru.iiec.pydroid3/files/arm-linux-androideabi/lib/python3.9/site-packages/kivy/base.py", line 308, in post_dispatch_input
[WARNING] stderr:     wid.dispatch('on_touch_up', me)
[WARNING] stderr:   File "kivy/_event.pyx", line 709, in kivy._event.EventDispatcher.dispatch
[WARNING] stderr:   File "/data/user/0/ru.iiec.pydroid3/files/arm-linux-androideabi/lib/python3.9/site-packages/kivy/uix/behaviors/button.py", line 179, in on_touch_up
[WARNING] stderr:     self.dispatch('on_release')
[WARNING] stderr:   File "kivy/_event.pyx", line 705, in kivy._event.EventDispatcher.dispatch
[WARNING] stderr:   File "kivy/_event.pyx", line 1248, in kivy._event.EventObservers.dispatch
[WARNING] stderr:   File "kivy/_event.pyx", line 1172, in kivy._event.EventObservers._dispatch
[WARNING] stderr:   File "/storage/emulated/0/Python/Testes/Views/SignUp.py", line 70, in signup
[WARNING] stderr:     client_controller.signup(self.view.ids.cpf.text, 
[WARNING] stderr:   File "/storage/emulated/0/Python/Testes/Controllers/client_controller.py", line 34, in signup
[WARNING] stderr:     response = ClientDAO.insert(connection_controller.get_connection(), client)
[WARNING] stderr:   File "/storage/emulated/0/Python/Testes/DAOs/Client.py", line 64, in insert
[WARNING] stderr:     cursor.execute(query, args)
[WARNING] stderr:   File "/data/user/0/ru.iiec.pydroid3/files/arm-linux-androideabi/lib/python3.9/site-packages/mysql/connector/cursor.py", line 551, in execute
[WARNING] stderr:     self._handle_result(self._connection.cmd_query(stmt))
[WARNING] stderr:   File "/data/user/0/ru.iiec.pydroid3/files/arm-linux-androideabi/lib/python3.9/site-packages/mysql/connector/connection.py", line 490, in cmd_query
[WARNING] stderr:     result = self._handle_result(self._send_cmd(ServerCmd.QUERY, query))
[WARNING] stderr:   File "/data/user/0/ru.iiec.pydroid3/files/arm-linux-androideabi/lib/python3.9/site-packages/mysql/connector/connection.py", line 395, in _handle_result
[WARNING] stderr:     raise errors.get_exception(packet)
[WARNING] stderr: mysql.connector.errors.DataError: 1366 (22007): Incorrect integer value: '' for column `bakery`.`clients`.`s_phone` at row 1
